<?xml version="1.0" encoding="utf-8"?><testsuites><testsuite errors="1" failures="0" hostname="DESKTOP-57N0HN9" name="pytest" skipped="0" tests="2" time="15.944" timestamp="2020-09-10T16:22:17.828586"><testcase classname="test_dir.test_baidu.TestSearch" file="test_dir\test_baidu.py" line="17" name="test_baidu_search_case" time="7.833"></testcase><testcase classname="pytest" name="internal" time="0.000"><error message="internal error">Traceback (most recent call last):
  File &quot;C:\Python\lib\site-packages\_pytest\main.py&quot;, line 191, in wrap_session
    session.exitstatus = doit(config, session) or 0
  File &quot;C:\Python\lib\site-packages\_pytest\main.py&quot;, line 247, in _main
    config.hook.pytest_runtestloop(session=session)
  File &quot;C:\Python\lib\site-packages\pluggy\hooks.py&quot;, line 286, in __call__
    return self._hookexec(self, self.get_hookimpls(), kwargs)
  File &quot;C:\Python\lib\site-packages\pluggy\manager.py&quot;, line 93, in _hookexec
    return self._inner_hookexec(hook, methods, kwargs)
  File &quot;C:\Python\lib\site-packages\pluggy\manager.py&quot;, line 84, in &lt;lambda&gt;
    self._inner_hookexec = lambda hook, methods, kwargs: hook.multicall(
  File &quot;C:\Python\lib\site-packages\pluggy\callers.py&quot;, line 208, in _multicall
    return outcome.get_result()
  File &quot;C:\Python\lib\site-packages\pluggy\callers.py&quot;, line 80, in get_result
    raise ex[1].with_traceback(ex[2])
  File &quot;C:\Python\lib\site-packages\pluggy\callers.py&quot;, line 187, in _multicall
    res = hook_impl.function(*args)
  File &quot;C:\Python\lib\site-packages\_pytest\main.py&quot;, line 272, in pytest_runtestloop
    item.config.hook.pytest_runtest_protocol(item=item, nextitem=nextitem)
  File &quot;C:\Python\lib\site-packages\pluggy\hooks.py&quot;, line 286, in __call__
    return self._hookexec(self, self.get_hookimpls(), kwargs)
  File &quot;C:\Python\lib\site-packages\pluggy\manager.py&quot;, line 93, in _hookexec
    return self._inner_hookexec(hook, methods, kwargs)
  File &quot;C:\Python\lib\site-packages\pluggy\manager.py&quot;, line 84, in &lt;lambda&gt;
    self._inner_hookexec = lambda hook, methods, kwargs: hook.multicall(
  File &quot;C:\Python\lib\site-packages\pluggy\callers.py&quot;, line 208, in _multicall
    return outcome.get_result()
  File &quot;C:\Python\lib\site-packages\pluggy\callers.py&quot;, line 80, in get_result
    raise ex[1].with_traceback(ex[2])
  File &quot;C:\Python\lib\site-packages\pluggy\callers.py&quot;, line 187, in _multicall
    res = hook_impl.function(*args)
  File &quot;C:\Python\lib\site-packages\pytest_rerunfailures.py&quot;, line 200, in pytest_runtest_protocol
    reports = runtestprotocol(item, nextitem=nextitem, log=False)
  File &quot;C:\Python\lib\site-packages\_pytest\runner.py&quot;, line 100, in runtestprotocol
    reports.append(call_and_report(item, &quot;call&quot;, log))
  File &quot;C:\Python\lib\site-packages\_pytest\runner.py&quot;, line 188, in call_and_report
    report = hook.pytest_runtest_makereport(item=item, call=call)
  File &quot;C:\Python\lib\site-packages\pluggy\hooks.py&quot;, line 286, in __call__
    return self._hookexec(self, self.get_hookimpls(), kwargs)
  File &quot;C:\Python\lib\site-packages\pluggy\manager.py&quot;, line 93, in _hookexec
    return self._inner_hookexec(hook, methods, kwargs)
  File &quot;C:\Python\lib\site-packages\pluggy\manager.py&quot;, line 84, in &lt;lambda&gt;
    self._inner_hookexec = lambda hook, methods, kwargs: hook.multicall(
  File &quot;C:\Python\lib\site-packages\pluggy\callers.py&quot;, line 203, in _multicall
    gen.send(outcome)
  File &quot;D:\Git\pyautoTest\conftest.py&quot;, line 52, in pytest_runtest_makereport
    capture_screenshots(case_name)
  File &quot;D:\Git\pyautoTest\conftest.py&quot;, line 99, in capture_screenshots
    RunConfig.driver.save_screenshot(image_dir)
  File &quot;C:\Python\lib\site-packages\selenium\webdriver\remote\webdriver.py&quot;, line 1055, in save_screenshot
    return self.get_screenshot_as_file(filename)
  File &quot;C:\Python\lib\site-packages\selenium\webdriver\remote\webdriver.py&quot;, line 1032, in get_screenshot_as_file
    png = self.get_screenshot_as_png()
  File &quot;C:\Python\lib\site-packages\selenium\webdriver\remote\webdriver.py&quot;, line 1064, in get_screenshot_as_png
    return base64.b64decode(self.get_screenshot_as_base64().encode(&apos;ascii&apos;))
  File &quot;C:\Python\lib\site-packages\selenium\webdriver\remote\webdriver.py&quot;, line 1074, in get_screenshot_as_base64
    return self.execute(Command.SCREENSHOT)[&apos;value&apos;]
  File &quot;C:\Python\lib\site-packages\selenium\webdriver\remote\webdriver.py&quot;, line 321, in execute
    self.error_handler.check_response(response)
  File &quot;C:\Python\lib\site-packages\selenium\webdriver\remote\errorhandler.py&quot;, line 242, in check_response
    raise exception_class(message, screen, stacktrace)
selenium.common.exceptions.NoSuchWindowException: Message: no such window: target window already closed
from unknown error: web view not found
  (Session info: chrome=85.0.4183.83)</error></testcase></testsuite></testsuites>